Workbook

Sheet Team Wise
A1: Hackathon – Team-wise Participant List (Attendance & Evaluation)
A2: Each team appears once (merged S.No / ID / Team Name / Track, and College/Branch/Year where identical). Teams are grouped by Track (alternate shading per team, thick line between teams). Fill the yellow Attendance column using the dropdown (Present / Absent).
A4: S.No | B4: Registration ID | C4: Team Name | D4: Team Member Name | E4: Role | F4: College | G4: Branch | H4: Year | I4: Track | J4: Phone No. | K4: Attendance
A5: 1 | B5: HV2-2026-OCT-4698 | C5: #HackNova | D5: Pasham Akanksha Reddy | E5: Leader | F5: Vignan Institute of Technology and Science | G5: AIDS | H5: 1st Year | I5: Artificial Intelligence (AI) | J5: 9652601387
D6: Srinivas Nayak Ramavath | E6: Member | J6: 7680028395
D7: Pasham Hrithik Reddy | E7: Member | J7: 8985540655
A8: 2 | B8: HV2-2026-OCT-1818 | C8: AI mavericks | D8: Vaggu Sahasra | E8: Leader | F8: Vignan Institute of Technology and Science | G8: CSE (DS) | H8: 2nd Year | I8: Artificial Intelligence (AI) | J8: 9908982106
D9: krupalini kasoju | E9: Member | G9: CIVIL | J9: 9100326179
D10: Gangapuram Sai Charan | E10: Member | G10: MECH | J10: 9666895769
A11: 3 | B11: HV2-2026-OCT-1348 | C11: AI-tians | D11: Mikkilineni Pravarshitha | E11: Leader | F11: Vignan Institute of Technology and Science | G11: CSE (AI&ML) | H11: 2nd Year | I11: Artificial Intelligence (AI) | J11: 8985359921
D12: P Pranathi | E12: Member | J12: 9381261938
D13: SINGAM SAI HARSHITH | E13: Member | J13: 7660042977
A14: 4 | B14: HV2-2026-OCT-4899 | C14: ARITRA | D14: Chathur M | E14: Leader | F14: Vignan Institute of Technology and Science | G14: AIDS | H14: 2nd Year | I14: Artificial Intelligence (AI) | J14: 9291619080
D15: Vaahini G | E15: Member | G15: AIDS | H15: 2nd Year | J15: 9391286222
D16: p sandeep | E16: Member | G16: CSE (DS) | H16: 3rd Year | J16: 7093447407
A17: 5 | B17: HV2-2026-OCT-4878 | C17: Advitheeya | D17: Badugu Nigama | E17: Leader | F17: Vignan Institute of Technology and Science | G17: AIDS | H17: 2nd Year | I17: Artificial Intelligence (AI) | J17: 7032177918
D18: Nakarakanti Yuva Keerthi | E18: Member | J18: 8074382611
D19: Kan Kushi Kumari | E19: Member | J19: 9490706546
A20: 6 | B20: HV2-2026-OCT-4104 | C20: Aevora | D20: Praseeja Sunkari | E20: Leader | F20: Vignan Institute of Technology and Science | G20: CSE (AI&ML) | H20: 3rd Year | I20: Artificial Intelligence (AI) | J20: 7842731141
D21: Vanja Akshitha | E21: Member | G21: CSE (DS) | J21: 7569220914
D22: B.Vaishnavi | E22: Member | G22: CSE (DS) | J22: 7416127993
A23: 7 | B23: HV2-2026-OCT-4906 | C23: AiFinishers | D23: Badavath vishnu | E23: Leader | F23: Vignan Institute of Technology and Science | G23: CSE (DS) | H23: 2nd Year | I23: Artificial Intelligence (AI) | J23: 7396616379
D24: Boya mukesh | E24: Member | J24: 7815858411
D25: Janga chandan | E25: Member | J25: 8247030165
A26: 8 | B26: HV2-2026-OCT-5358 | C26: Al Avengers | D26: Sathu. Goutham Reddy | E26: Leader | F26: Vignan Institute of Technology and Science | G26: CSE (DS) | H26: 3rd Year | I26: Artificial Intelligence (AI) | J26: 9154184676
D27: Gudipelli. Manoj | E27: Member | G27: CSE (AI&ML) | J27: 8179544286
D28: Kongari. Udayasree | E28: Member | G28: CSE (DS) | J28: 6303036707
A29: 9 | B29: HV2-2026-OCT-4614 | C29: Algo squad | D29: Poloju vasavi | E29: Leader | F29: Vignan Institute of Technology and Science | G29: CSE | H29: 3rd Year | I29: Artificial Intelligence (AI) | J29: 9392793987
D30: Mohammad saniya | E30: Member | J30: 9848364850
D31: Pittala harika | E31: Member | J31: 6309460308
A32: 10 | B32: HV2-2026-OCT-2695 | C32: Alide | D32: Abhiram | E32: Leader | F32: Vignan Institute of Technology and Science | G32: CSE (AI&ML) | H32: 2nd Year | I32: Artificial Intelligence (AI) | J32: 8008189293
D33: Mohammad Arif | E33: Member | J33: 8074047607
D34: Sathish | E34: Member | J34: 8712214574
A35: 11 | B35: HV2-2026-OCT-7565 | C35: All stars | D35: katakam supraja | E35: Leader | F35: Vignan Institute of Technology and Science | G35: CSE | H35: 2nd Year | I35: Artificial Intelligence (AI) | J35: 9490948538
D36: N.arun | E36: Member | J36: 8639459203
D37: M ARAVIND | E37: Member | J37: 6281094261
A38: 12 | B38: HV2-2026-OCT-4338 | C38: BLITZ | D38: Tejeshwar Reddy Addula | E38: Leader | F38: Vignan Institute of Technology and Science | G38: CSE (AI&ML) | H38: 2nd Year | I38: Artificial Intelligence (AI) | J38: 7382838743
D39: Byreddy Sushank Reddy | E39: Member | J39: 8332051480
D40: Chandaluri Sri Harsha | E40: Member | J40: 9100865190
A41: 13 | B41: HV2-2026-OCT-5946 | C41: Bits x Bytes | D41: Neha Reddy K | E41: Leader | F41: Vignan Institute of Technology and Science | G41: CSE (DS) | H41: 3rd Year | I41: Artificial Intelligence (AI) | J41: 7093677995
...

Sheet Team Evaluation
A1: Hackathon – Team Evaluation Sheet
A2: Enter marks in the yellow cells (max marks shown in row 4; criteria names & max marks are placeholders – edit as needed). Total, Percentage and Track Rank calculate automatically. Members Present comes from the Attendance column on Team Wise. College/Branch/Year are shown once if the whole team is the same, otherwise one line per member in the same order as the names; Phone has one line per member.
K4: Max marks → | L4: 10 | M4: 10 | N4: 10 | O4: 10 | P4: =SUM(L4:O4) -> 40
A5: Team No. | B5: Registration ID | C5: Team Name | D5: Track | E5: Team Member Names | F5: College | G5: Branch | H5: Year | I5: Phone No. | J5: Members | K5: Members Present | L5: Innovation / Idea | M5: Technical Implementation | N5: Feasibility / Impact | O5: Presentation & Demo | P5: Total | Q5: Percentage | R5: Rank in Track | S5: Remarks
A6: 1 | B6: HV2-2026-OCT-4698 | C6: #HackNova | D6: Artificial Intelligence (AI) | E6: Pasham Akanksha Reddy Srinivas Nayak Ramavath Pasham Hrithik Reddy | F6: Vignan Institute of Technology and Science | G6: AIDS | H6: 1st Year | I6: 9652601387 7680028395 8985540655 | J6: =COUNTA('Team Wise'!D5:D7) -> 3 | K6: =COUNTIF('Team Wise'!K5:K7,"Present") -> 0 | P6: =IF(COUNT(L6:O6)=0,"",SUM(L6:O6)) | Q6: =IF(P6="","",P6/$P$4) | R6: =IF(P6="","",COUNTIFS($D$6:$D$219,D6,$P$6:$P$219,">"&P6)+1)
A7: 2 | B7: HV2-2026-OCT-1818 | C7: AI mavericks | D7: Artificial Intelligence (AI) | E7: Vaggu Sahasra krupalini kasoju Gangapuram Sai Charan | F7: Vignan Institute of Technology and Science | G7: CSE (DS) CIVIL MECH | H7: 2nd Year | I7: 9908982106 9100326179 9666895769 | J7: =COUNTA('Team Wise'!D8:D10) -> 3 | K7: =COUNTIF('Team Wise'!K8:K10,"Present") -> 0 | P7: =IF(COUNT(L7:O7)=0,"",SUM(L7:O7)) | Q7: =IF(P7="","",P7/$P$4) | R7: =IF(P7="","",COUNTIFS($D$6:$D$219,D7,$P$6:$P$219,">"&P7)+1)
A8: 3 | B8: HV2-2026-OCT-1348 | C8: AI-tians | D8: Artificial Intelligence (AI) | E8: Mikkilineni Pravarshitha P Pranathi SINGAM SAI HARSHITH | F8: Vignan Institute of Technology and Science | G8: CSE (AI&ML) | H8: 2nd Year | I8: 8985359921 9381261938 7660042977 | J8: =COUNTA('Team Wise'!D11:D13) -> 3 | K8: =COUNTIF('Team Wise'!K11:K13,"Present") -> 0 | P8: =IF(COUNT(L8:O8)=0,"",SUM(L8:O8)) | Q8: =IF(P8="","",P8/$P$4) | R8: =IF(P8="","",COUNTIFS($D$6:$D$219,D8,$P$6:$P$219,">"&P8)+1)
A9: 4 | B9: HV2-2026-OCT-4899 | C9: ARITRA | D9: Artificial Intelligence (AI) | E9: Chathur M Vaahini G p sandeep | F9: Vignan Institute of Technology and Science | G9: AIDS AIDS CSE (DS) | H9: 2nd Year 2nd Year 3rd Year | I9: 9291619080 9391286222 7093447407 | J9: =COUNTA('Team Wise'!D14:D16) -> 3 | K9: =COUNTIF('Team Wise'!K14:K16,"Present") -> 0 | P9: =IF(COUNT(L9:O9)=0,"",SUM(L9:O9)) | Q9: =IF(P9="","",P9/$P$4) | R9: =IF(P9="","",COUNTIFS($D$6:$D$219,D9,$P$6:$P$219,">"&P9)+1)
A10: 5 | B10: HV2-2026-OCT-4878 | C10: Advitheeya | D10: Artificial Intelligence (AI) | E10: Badugu Nigama Nakarakanti Yuva Keerthi Kan Kushi Kumari | F10: Vignan Institute of Technology and Science | G10: AIDS | H10: 2nd Year | I10: 7032177918 8074382611 9490706546 | J10: =COUNTA('Team Wise'!D17:D19) -> 3 | K10: =COUNTIF('Team Wise'!K17:K19,"Present") -> 0 | P10: =IF(COUNT(L10:O10)=0,"",SUM(L10:O10)) | Q10: =IF(P10="","",P10/$P$4) | R10: =IF(P10="","",COUNTIFS($D$6:$D$219,D10,$P$6:$P$219,">"&P10)+1)
A11: 6 | B11: HV2-2026-OCT-4104 | C11: Aevora | D11: Artificial Intelligence (AI) | E11: Praseeja Sunkari Vanja Akshitha B.Vaishnavi | F11: Vignan Institute of Technology and Science | G11: CSE (AI&ML) CSE (DS) CSE (DS) | H11: 3rd Year | I11: 7842731141 7569220914 7416127993 | J11: =COUNTA('Team Wise'!D20:D22) -> 3 | K11: =COUNTIF('Team Wise'!K20:K22,"Present") -> 0 | P11: =IF(COUNT(L11:O11)=0,"",SUM(L11:O11)) | Q11: =IF(P11="","",P11/$P$4) | R11: =IF(P11="","",COUNTIFS($D$6:$D$219,D11,$P$6:$P$219,">"&P11)+1)
A12: 7 | B12: HV2-2026-OCT-4906 | C12: AiFinishers | D12: Artificial Intelligence (AI) | E12: Badavath vishnu Boya mukesh Janga chandan | F12: Vignan Institute of Technology and Science | G12: CSE (DS) | H12: 2nd Year | I12: 7396616379 7815858411 8247030165 | J12: =COUNTA('Team Wise'!D23:D25) -> 3 | K12: =COUNTIF('Team Wise'!K23:K25,"Present") -> 0 | P12: =IF(COUNT(L12:O12)=0,"",SUM(L12:O12)) | Q12: =IF(P12="","",P12/$P$4) | R12: =IF(P12="","",COUNTIFS($D$6:$D$219,D12,$P$6:$P$219,">"&P12)+1)
A13: 8 | B13: HV2-2026-OCT-5358 | C13: Al Avengers | D13: Artificial Intelligence (AI) | E13: Sathu. Goutham Reddy Gudipelli. Manoj Kongari. Udayasree | F13: Vignan Institute of Technology and Science | G13: CSE (DS) CSE (AI&ML) CSE (DS) | H13: 3rd Year | I13: 9154184676 8179544286 6303036707 | J13: =COUNTA('Team Wise'!D26:D28) -> 3 | K13: =COUNTIF('Team Wise'!K26:K28,"Present") -> 0 | P13: =IF(COUNT(L13:O13)=0,"",SUM(L13:O13)) | Q13: =IF(P13="","",P13/$P$4) | R13: =IF(P13="","",COUNTIFS($D$6:$D$219,D13,$P$6:$P$219,">"&P13)+1)
A14: 9 | B14: HV2-2026-OCT-4614 | C14: Algo squad | D14: Artificial Intelligence (AI) | E14: Poloju vasavi Mohammad saniya Pittala harika | F14: Vignan Institute of Technology and Science | G14: CSE | H14: 3rd Year | I14: 9392793987 9848364850 6309460308 | J14: =COUNTA('Team Wise'!D29:D31) -> 3 | K14: =COUNTIF('Team Wise'!K29:K31,"Present") -> 0 | P14: =IF(COUNT(L14:O14)=0,"",SUM(L14:O14)) | Q14: =IF(P14="","",P14/$P$4) | R14: =IF(P14="","",COUNTIFS($D$6:$D$219,D14,$P$6:$P$219,">"&P14)+1)
A15: 10 | B15: HV2-2026-OCT-2695 | C15: Alide | D15: Artificial Intelligence (AI) | E15: Abhiram Mohammad Arif Sathish | F15: Vignan Institute of Technology and Science | G15: CSE (AI&ML) | H15: 2nd Year | I15: 8008189293 8074047607 8712214574 | J15: =COUNTA('Team Wise'!D32:D34) -> 3 | K15: =COUNTIF('Team Wise'!K32:K34,"Present") -> 0 | P15: =IF(COUNT(L15:O15)=0,"",SUM(L15:O15)) | Q15: =IF(P15="","",P15/$P$4) | R15: =IF(P15="","",COUNTIFS($D$6:$D$219,D15,$P$6:$P$219,">"&P15)+1)
A16: 11 | B16: HV2-2026-OCT-7565 | C16: All stars | D16: Artificial Intelligence (AI) | E16: katakam supraja N.arun M ARAVIND | F16: Vignan Institute of Technology and Science | G16: CSE | H16: 2nd Year | I16: 9490948538 8639459203 6281094261 | J16: =COUNTA('Team Wise'!D35:D37) -> 3 | K16: =COUNTIF('Team Wise'!K35:K37,"Present") -> 0 | P16: =IF(COUNT(L16:O16)=0,"",SUM(L16:O16)) | Q16: =IF(P16="","",P16/$P$4) | R16: =IF(P16="","",COUNTIFS($D$6:$D$219,D16,$P$6:$P$219,">"&P16)+1)
A17: 12 | B17: HV2-2026-OCT-4338 | C17: BLITZ | D17: Artificial Intelligence (AI) | E17: Tejeshwar Reddy Addula Byreddy Sushank Reddy Chandaluri Sri Harsha | F17: Vignan Institute of Technology and Science | G17: CSE (AI&ML) | H17: 2nd Year | I17: 7382838743 8332051480 9100865190 | J17: =COUNTA('Team Wise'!D38:D40) -> 3 | K17: =COUNTIF('Team Wise'!K38:K40,"Present") -> 0 | P17: =IF(COUNT(L17:O17)=0,"",SUM(L17:O17)) | Q17: =IF(P17="","",P17/$P$4) | R17: =IF(P17="","",COUNTIFS($D$6:$D$219,D17,$P$6:$P$219,">"&P17)+1)
A18: 13 | B18: HV2-2026-OCT-5946 | C18: Bits x Bytes | D18: Artificial Intelligence (AI) | E18: Neha Reddy K Koduri Sri Harsha I Sahasra | F18: Vignan Institute of Technology and Science | G18: CSE (DS) CSE CSE (DS) | H18: 3rd Year | I18: 7093677995 9652867531 9347883612 | J18: =COUNTA('Team Wise'!D41:D43) -> 3 | K18: =COUNTIF('Team Wise'!K41:K43,"Present") -> 0 | P18: =IF(COUNT(L18:O18)=0,"",SUM(L18:O18)) | Q18: =IF(P18="","",P18/$P$4) | R18: =IF(P18="","",COUNTIFS($D$6:$D$219,D18,$P$6:$P$219,">"&P18)+1)
A19: 14 | B19: HV2-2026-OCT-6520 | C19: Black Pearl | D19: Artificial Intelligence (AI) | E19: Danthenapally Srivarshitha Gollapalli Chakradhar Chary Kota Uday Reddy | F19: CVR College of Engineering Sri Venkateshwara College of Engineering CVR College of Engineering | G19: CSE (DS) CSE (AI&ML) CSE (DS) | H19: 2nd Year | I19: 6309934781 7013280417 9347004550 | J19: =COUNTA('Team Wise'!D44:D46) -> 3 | K19: =COUNTIF('Team Wise'!K44:K46,"Present") -> 0 | P19: =IF(COUNT(L19:O19)=0,"",SUM(L19:O19)) | Q19: =IF(P19="","",P19/$P$4) | R19: =IF(P19="","",COUNTIFS($D$6:$D$219,D19,$P$6:$P$219,">"&P19)+1)
A20: 15 | B20: HV2-2026-OCT-4594 | C20: BoldCoders | D20: Artificial Intelligence (AI) | E20: Kasoju SpuranChandra Maddineni Yashashwini Pothuganti Sonalika | F20: Vignan Institute of Technology and Science | G20: CSE | H20: 2nd Year | I20: 9515067709 7793963851 8332044969 | J20: =COUNTA('Team Wise'!D47:D49) -> 3 | K20: =COUNTIF('Team Wise'!K47:K49,"Present") -> 0 | P20: =IF(COUNT(L20:O20)=0,"",SUM(L20:O20)) | Q20: =IF(P20="","",P20/$P$4) | R20: =IF(P20="","",COUNTIFS($D$6:$D$219,D20,$P$6:$P$219,">"&P20)+1)
A21: 16 | B21: HV2-2026-OCT-3585 | C21: BrainRot Brats | D21: Artificial Intelligence (AI) | E21: Aasheerwad Sandhyapogu Vishal reddy Syed Omer | F21: Vignan Institute of Technology and Science | G21: CSE (AI&ML) | H21: 3rd Year | I21: 7702363562 9849019832 7981537348 | J21: =COUNTA('Team Wise'!D50:D52) -> 3 | K21: =COUNTIF('Team Wise'!K50:K52,"Present") -> 0 | P21: =IF(COUNT(L21:O21)=0,"",SUM(L21:O21)) | Q21: =IF(P21="","",P21/$P$4) | R21: =IF(P21="","",COUNTIFS($D$6:$D$219,D21,$P$6:$P$219,">"&P21)+1)
A22: 17 | B22: HV2-2026-OCT-3629 | C22: BroCode | D22: Artificial Intelligence (AI) | E22: Varshini Bodige Harika Gummalla Kancharla Manish Kumar | F22: Vignan Institute of Technology and Science | G22: CSE | H22: 2nd Year | I22: 9182392386 9121555751 9948437820 | J22: =COUNTA('Team Wise'!D53:D55) -> 3 | K22: =COUNTIF('Team Wise'!K53:K55,"Present") -> 0 | P22: =IF(COUNT(L22:O22)=0,"",SUM(L22:O22)) | Q22: =IF(P22="","",P22/$P$4) | R22: =IF(P22="","",COUNTIFS($D$6:$D$219,D22,$P$6:$P$219,">"&P22)+1)
A23: 18 | B23: HV2-2026-OCT-4616 | C23: Bug Slayers | D23: Artificial Intelligence (AI) | E23: Padarthi Divya Sri Chirra Hasini Chamakura Yamini | F23: ACE Engineering College | G23: CSE (DS) CSE (AI&ML) CSE (DS) | H23: 2nd Year | I23: 9618719572 8341223438 7989609328 | J23: =COUNTA('Team Wise'!D56:D58) -> 3 | K23: =COUNTIF('Team Wise'!K56:K58,"Present") -> 0 | P23: =IF(COUNT(L23:O23)=0,"",SUM(L23:O23)) | Q23: =IF(P23="","",P23/$P$4) | R23: =IF(P23="","",COUNTIFS($D$6:$D$219,D23,$P$6:$P$219,">"&P23)+1)
A24: 19 | B24: HV2-2026-OCT-9242 | C24: Clause's Plan | D24: Artificial Intelligence (AI) | E24: Sashreek Reddy Kanaparthy Aryan Sai Chandrakanth | F24: Vignan Institute of Technology and Science | G24: CSE | H24: 2nd Year | I24: 9059949889 7416481279 6281696284 | J24: =COUNTA('Team Wise'!D59:D61) -> 3 | K24: =COUNTIF('Team Wise'!K59:K61,"Present") -> 0 | P24: =IF(COUNT(L24:O24)=0,"",SUM(L24:O24)) | Q24: =IF(P24="","",P24/$P$4) | R24: =IF(P24="","",COUNTIFS($D$6:$D$219,D24,$P$6:$P$219,">"&P24)+1)
A25: 20 | B25: HV2-2026-OCT-9150 | C25: Code & Slay | D25: Artificial Intelligence (AI) | E25: Anthati Ruthika Ithagoni Jyothsnasri Kusuru Divya | F25: Vignan Institute of Technology and Science | G25: CSE | H25: 3rd Year | I25: 9705884131 9121954394 9391433725 | J25: =COUNTA('Team Wise'!D62:D64) -> 3 | K25: =COUNTIF('Team Wise'!K62:K64,"Present") -> 0 | P25: =IF(COUNT(L25:O25)=0,"",SUM(L25:O25)) | Q25: =IF(P25="","",P25/$P$4) | R25: =IF(P25="","",COUNTIFS($D$6:$D$219,D25,$P$6:$P$219,">"&P25)+1)
A26: 21 | B26: HV2-2026-OCT-5745 | C26: Code Blooded | D26: Artificial Intelligence (AI) | E26: Yamini Thirumani Puvvadi Sakhitha Harshitha Puliroju | F26: G Narayanamma Institute of Technology and Science (GNITS) | G26: CSE (DS) CSE (AI&ML) CSE (DS) | H26: 4th Year | I26: 7995693895 9398899334 6305406660 | J26: =COUNTA('Team Wise'!D65:D67) -> 3 | K26: =COUNTIF('Team Wise'!K65:K67,"Present") -> 0 | P26: =IF(COUNT(L26:O26)=0,"",SUM(L26:O26)) | Q26: =IF(P26="","",P26/$P$4) | R26: =IF(P26="","",COUNTIFS($D$6:$D$219,D26,$P$6:$P$219,">"&P26)+1)
A27: 22 | B27: HV2-2026-OCT-6128 | C27: Code cube | D27: Artificial Intelligence (AI) | E27: Padakanti varsha Ubbu Rohini Palsam Maneesha | F27: Vignan Institute of Technology and Science | G27: CSE | H27: 3rd Year | I27: 6304218536 9603272908 9014710274 | J27: =COUNTA('Team Wise'!D68:D70) -> 3 | K27: =COUNTIF('Team Wise'!K68:K70,"Present") -> 0 | P27: =IF(COUNT(L27:O27)=0,"",SUM(L27:O27)) | Q27: =IF(P27="","",P27/$P$4) | R27: =IF(P27="","",COUNTIFS($D$6:$D$219,D27,$P$6:$P$219,">"&P27)+1)
A28: 23 | B28: HV2-2026-OCT-4305 | C28: Code rush | D28: Artificial Intelligence (AI) | E28: chegurisahasra21 chegurisamaghna21 shivaniappala | F28: Vignan Institute of Technology and Science | G28: CSE | H28: 3rd Year | I28: 9573609225 9849747585 6304128615 | J28: =COUNTA('Team Wise'!D71:D73) -> 3 | K28: =COUNTIF('Team Wise'!K71:K73,"Present") -> 0 | P28: =IF(COUNT(L28:O28)=0,"",SUM(L28:O28)) | Q28: =IF(P28="","",P28/$P$4) | R28: =IF(P28="","",COUNTIFS($D$6:$D$219,D28,$P$6:$P$219,">"&P28)+1)
A29: 24 | B29: HV2-2026-OCT-5660 | C29: Code titans | D29: Artificial Intelligence (AI) | E29: Chada Vaishnavi Akshitha Deshagoni Srividya Alubilli | F29: Marri Laxman Reddy Institute of Technology and Management (MLRITM) | G29: CSE (AI&ML) | H29: 2nd Year | I29: 7702498268 9030380871 6281084832 | J29: =COUNTA('Team Wise'!D74:D76) -> 3 | K29: =COUNTIF('Team Wise'!K74:K76,"Present") -> 0 | P29: =IF(COUNT(L29:O29)=0,"",SUM(L29:O29)) | Q29: =IF(P29="","",P29/$P$4) | R29: =IF(P29="","",COUNTIFS($D$6:$D$219,D29,$P$6:$P$219,">"&P29)+1)
A30: 25 | B30: HV2-2026-OCT-9845 | C30: Code titans | D30: Artificial Intelligence (AI) | E30: Chindam Keerthana janipella sindhu tadaka akhila | F30: Vignan Institute of Technology and Science | G30: CSE (AI&ML) | H30: 2nd Year | I30: 8179992289 9573376307 8688196471 | J30: =COUNTA('Team Wise'!D77:D79) -> 3 | K30: =COUNTIF('Team Wise'!K77:K79,"Present") -> 0 | P30: =IF(COUNT(L30:O30)=0,"",SUM(L30:O30)) | Q30: =IF(P30="","",P30/$P$4) | R30: =IF(P30="","",COUNTIFS($D$6:$D$219,D30,$P$6:$P$219,">"&P30)+1)
A31: 26 | B31: HV2-2026-OCT-8620 | C31: Code × Crash | D31: Artificial Intelligence (AI) | E31: Daroori Abhignya S.Ruchitha Tejaswi Pendyala | F31: Vignan's Institute of Management and Technology for Women (VMTW) | G31: CSE (DS) | H31: 3rd Year | I31: 8247203142 9866193388 9391281815 | J31: =COUNTA('Team Wise'!D80:D82) -> 3 | K31: =COUNTIF('Team Wise'!K80:K82,"Present") -> 0 | P31: =IF(COUNT(L31:O31)=0,"",SUM(L31:O31)) | Q31: =IF(P31="","",P31/$P$4) | R31: =IF(P31="","",COUNTIFS($D$6:$D$219,D31,$P$6:$P$219,">"&P31)+1)
A32: 27 | B32: HV2-2026-OCT-6582 | C32: CodeAlpha | D32: Artificial Intelligence (AI) | E32: Golconda Yeshwanth Kumar Polepaka Mahesh Velpula Vyshali | F32: Anurag Engineering College (Kodad) | G32: CSE | H32: 3rd Year | I32: 7075320652 7013197272 9542224334 | J32: =COUNTA('Team Wise'!D83:D85) -> 3 | K32: =COUNTIF('Team Wise'!K83:K85,"Present") -> 0 | P32: =IF(COUNT(L32:O32)=0,"",SUM(L32:O32)) | Q32: =IF(P32="","",P32/$P$4) | R32: =IF(P32="","",COUNTIFS($D$6:$D$219,D32,$P$6:$P$219,">"&P32)+1)
A33: 28 | B33: HV2-2026-OCT-5487 | C33: CodeHelix | D33: Artificial Intelligence (AI) | E33: G.Rishitha K.shirisha Gondi Soumya reddy | F33: Vignan Institute of Technology and Science | G33: CSE | H33: 3rd Year | I33: 7997182157 9652166330 9848546409 | J33: =COUNTA('Team Wise'!D86:D88) -> 3 | K33: =COUNTIF('Team Wise'!K86:K88,"Present") -> 0 | P33: =IF(COUNT(L33:O33)=0,"",SUM(L33:O33)) | Q33: =IF(P33="","",P33/$P$4) | R33: =IF(P33="","",COUNTIFS($D$6:$D$219,D33,$P$6:$P$219,">"&P33)+1)
A34: 29 | B34: HV2-2026-OCT-3917 | C34: CodeMatriX | D34: Artificial Intelligence (AI) | E34: Krishna Chaitanya Anugu Nandini Yarramada Ashna Reddy Gangapuram | F34: Vignan Institute of Technology and Science | G34: CSE | H34: 2nd Year | I34: 7780401460 9063401449 9393833639 | J34: =COUNTA('Team Wise'!D89:D91) -> 3 | K34: =COUNTIF('Team Wise'!K89:K91,"Present") -> 0 | P34: =IF(COUNT(L34:O34)=0,"",SUM(L34:O34)) | Q34: =IF(P34="","",P34/$P$4) | R34: =IF(P34="","",COUNTIFS($D$6:$D$219,D34,$P$6:$P$219,">"&P34)+1)
A35: 30 | B35: HV2-2026-OCT-1244 | C35: CodeMind | D35: Artificial Intelligence (AI) | E35: BHUDHALA MADHAVI KASULA AKSHAYA PREETHI BARADO | F35: Vignan Institute of Technology and Science | G35: CSE (DS) | H35: 2nd Year | I35: 8179752894 9032915256 9603554602 | J35: =COUNTA('Team Wise'!D92:D94) -> 3 | K35: =COUNTIF('Team Wise'!K92:K94,"Present") -> 0 | P35: =IF(COUNT(L35:O35)=0,"",SUM(L35:O35)) | Q35: =IF(P35="","",P35/$P$4) | R35: =IF(P35="","",COUNTIFS($D$6:$D$219,D35,$P$6:$P$219,">"&P35)+1)
A36: 31 | B36: HV2-2026-OCT-6039 | C36: Codefusion | D36: Artificial Intelligence (AI) | E36: SHIVANI KURMA Ch Karthik Shaik Momin | F36: Marri Laxman Reddy Institute of Technology and Management (MLRITM) | G36: CSE (AI&ML) | H36: 3rd Year | I36: 9398471837 9493317442 9133153170 | J36: =COUNTA('Team Wise'!D95:D97) -> 3 | K36: =COUNTIF('Team Wise'!K95:K97,"Present") -> 0 | P36: =IF(COUNT(L36:O36)=0,"",SUM(L36:O36)) | Q36: =IF(P36="","",P36/$P$4) | R36: =IF(P36="","",COUNTIFS($D$6:$D$219,D36,$P$6:$P$219,">"&P36)+1)
A37: 32 | B37: HV2-2026-OCT-5283 | C37: Coders | D37: Artificial Intelligence (AI) | E37: Neelam Anjali Nikhil Mudigonda Srujana Sadhu | F37: KL University (KLH) | G37: CSE | H37: 4th Year 3rd Year 3rd Year | I37: 9985859422 8341664756 9491516765 | J37: =COUNTA('Team Wise'!D98:D100) -> 3 | K37: =COUNTIF('Team Wise'!K98:K100,"Present") -> 0 | P37: =IF(COUNT(L37:O37)=0,"",SUM(L37:O37)) | Q37: =IF(P37="","",P37/$P$4) | R37: =IF(P37="","",COUNTIFS($D$6:$D$219,D37,$P$6:$P$219,">"&P37)+1)
A38: 33 | B38: HV2-2026-OCT-8480 | C38: Coderush | D38: Artificial Intelligence (AI) | E38: Erra Akshitha Varsha Mattaparthi Damaraju guru Lakshmi manasa | F38: Sphoorthy Engineering College Vignan Institute of Technology and Science Matrusri Engineering College | G38: AI&ML CSE IT | H38: 3rd Year | I38: 9441830190 7989068069 6309804359 | J38: =COUNTA('Team Wise'!D101:D103) -> 3 | K38: =COUNTIF('Team Wise'!K101:K103,"Present") -> 0 | P38: =IF(COUNT(L38:O38)=0,"",SUM(L38:O38)) | Q38: =IF(P38="","",P38/$P$4) | R38: =IF(P38="","",COUNTIFS($D$6:$D$219,D38,$P$6:$P$219,">"&P38)+1)
A39: 34 | B39: HV2-2026-OCT-2455 | C39: Codex | D39: Artificial Intelligence (AI) | E39: Lingamgunta Pranav Abhivarun Bashapaka Shivashritej | F39: Vignan Institute of Technology and Science | G39: CSE | H39: 2nd Year | I39: 8179146995 9515659290 8179222881 | J39: =COUNTA('Team Wise'!D104:D106) -> 3 | K39: =COUNTIF('Team Wise'!K104:K106,"Present") -> 0 | P39: =IF(COUNT(L39:O39)=0,"",SUM(L39:O39)) | Q39: =IF(P39="","",P39/$P$4) | R39: =IF(P39="","",COUNTIFS($D$6:$D$219,D39,$P$6:$P$219,">"&P39)+1)
A40: 35 | B40: HV2-2026-OCT-5681 | C40: Codex | D40: Artificial Intelligence (AI) | E40: KARIVEDA ABHINAV REDDY Kashamalla spandana Ulloju anitha | F40: Vignan Institute of Technology and Science | G40: CSE (AI&ML) | H40: 3rd Year | I40: 8985144115 9182364536 9014367708 | J40: =COUNTA('Team Wise'!D107:D109) -> 3 | K40: =COUNTIF('Team Wise'!K107:K109,"Present") -> 0 | P40: =IF(COUNT(L40:O40)=0,"",SUM(L40:O40)) | Q40: =IF(P40="","",P40/$P$4) | R40: =IF(P40="","",COUNTIFS($D$6:$D$219,D40,$P$6:$P$219,">"&P40)+1)
A41: 36 | B41: HV2-2026-OCT-5738 | C41: Codinjas | D41: Artificial Intelligence (AI) | E41: POLE RAVITEJA Varahala Vishal Yashraj Bhuvakar | F41: Vardhaman College of Engineering VMEG VMEG | G41: IT ECE ECE | H41: 3rd Year | I41: 7569057424 9701417442 7386614171 | J41: =COUNTA('Team Wise'!D110:D112) -> 3 | K41: =COUNTIF('Team Wise'!K110:K112,"Present") -> 0 | P41: =IF(COUNT(L41:O41)=0,"",SUM(L41:O41)) | Q41: =IF(P41="","",P41/$P$4) | R41: =IF(P41="","",COUNTIFS($D$6:$D$219,D41,$P$6:$P$219,">"&P41)+1)
...

Sheet AI
A5: Team No. | B5: Registration ID | C5: Team Name | D5: Track | E5: Team Member Names | F5: College | G5: Branch | H5: Year | I5: Phone No. | J5: Members
A6: 1 | B6: HV2-2026-OCT-4698 | C6: #HackNova | D6: Artificial Intelligence (AI) | E6: Pasham Akanksha Reddy Srinivas Nayak Ramavath Pasham Hrithik Reddy | F6: Vignan Institute of Technology and Science | G6: AIDS | H6: 1st Year | I6: 9652601387 7680028395 8985540655 | J6: 3
A7: 2 | B7: HV2-2026-OCT-1818 | C7: AI mavericks | D7: Artificial Intelligence (AI) | E7: Vaggu Sahasra krupalini kasoju Gangapuram Sai Charan | F7: Vignan Institute of Technology and Science | G7: CSE (DS) CIVIL MECH | H7: 2nd Year | I7: 9908982106 9100326179 9666895769 | J7: =COUNTA('Team Wise'!D6:D8) -> 3
A8: 3 | B8: HV2-2026-OCT-1348 | C8: AI-tians | D8: Artificial Intelligence (AI) | E8: Mikkilineni Pravarshitha P Pranathi SINGAM SAI HARSHITH | F8: Vignan Institute of Technology and Science | G8: CSE (AI&ML) | H8: 2nd Year | I8: 8985359921 9381261938 7660042977 | J8: =COUNTA('Team Wise'!D9:D11) -> 3
A9: 4 | B9: HV2-2026-OCT-4899 | C9: ARITRA | D9: Artificial Intelligence (AI) | E9: Chathur M Vaahini G p sandeep | F9: Vignan Institute of Technology and Science | G9: AIDS AIDS CSE (DS) | H9: 2nd Year 2nd Year 3rd Year | I9: 9291619080 9391286222 7093447407 | J9: =COUNTA('Team Wise'!D12:D14) -> 3
A10: 5 | B10: HV2-2026-OCT-4878 | C10: Advitheeya | D10: Artificial Intelligence (AI) | E10: Badugu Nigama Nakarakanti Yuva Keerthi Kan Kushi Kumari | F10: Vignan Institute of Technology and Science | G10: AIDS | H10: 2nd Year | I10: 7032177918 8074382611 9490706546 | J10: =COUNTA('Team Wise'!D15:D17) -> 3
A11: 6 | B11: HV2-2026-OCT-4104 | C11: Aevora | D11: Artificial Intelligence (AI) | E11: Praseeja Sunkari Vanja Akshitha B.Vaishnavi | F11: Vignan Institute of Technology and Science | G11: CSE (AI&ML) CSE (DS) CSE (DS) | H11: 3rd Year | I11: 7842731141 7569220914 7416127993 | J11: =COUNTA('Team Wise'!D18:D20) -> 3
A12: 7 | B12: HV2-2026-OCT-4906 | C12: AiFinishers | D12: Artificial Intelligence (AI) | E12: Badavath vishnu Boya mukesh Janga chandan | F12: Vignan Institute of Technology and Science | G12: CSE (DS) | H12: 2nd Year | I12: 7396616379 7815858411 8247030165 | J12: =COUNTA('Team Wise'!D21:D23) -> 3
A13: 8 | B13: HV2-2026-OCT-5358 | C13: Al Avengers | D13: Artificial Intelligence (AI) | E13: Sathu. Goutham Reddy Gudipelli. Manoj Kongari. Udayasree | F13: Vignan Institute of Technology and Science | G13: CSE (DS) CSE (AI&ML) CSE (DS) | H13: 3rd Year | I13: 9154184676 8179544286 6303036707 | J13: =COUNTA('Team Wise'!D24:D26) -> 3
A14: 9 | B14: HV2-2026-OCT-4614 | C14: Algo squad | D14: Artificial Intelligence (AI) | E14: Poloju vasavi Mohammad saniya Pittala harika | F14: Vignan Institute of Technology and Science | G14: CSE | H14: 3rd Year | I14: 9392793987 9848364850 6309460308 | J14: =COUNTA('Team Wise'!D27:D29) -> 3
A15: 10 | B15: HV2-2026-OCT-2695 | C15: Alide | D15: Artificial Intelligence (AI) | E15: Abhiram Mohammad Arif Sathish | F15: Vignan Institute of Technology and Science | G15: CSE (AI&ML) | H15: 2nd Year | I15: 8008189293 8074047607 8712214574 | J15: =COUNTA('Team Wise'!D30:D32) -> 3
A16: 11 | B16: HV2-2026-OCT-7565 | C16: All stars | D16: Artificial Intelligence (AI) | E16: katakam supraja N.arun M ARAVIND | F16: Vignan Institute of Technology and Science | G16: CSE | H16: 2nd Year | I16: 9490948538 8639459203 6281094261 | J16: =COUNTA('Team Wise'!D33:D35) -> 3
A17: 12 | B17: HV2-2026-OCT-4338 | C17: BLITZ | D17: Artificial Intelligence (AI) | E17: Tejeshwar Reddy Addula Byreddy Sushank Reddy Chandaluri Sri Harsha | F17: Vignan Institute of Technology and Science | G17: CSE (AI&ML) | H17: 2nd Year | I17: 7382838743 8332051480 9100865190 | J17: =COUNTA('Team Wise'!D36:D38) -> 3
A18: 13 | B18: HV2-2026-OCT-5946 | C18: Bits x Bytes | D18: Artificial Intelligence (AI) | E18: Neha Reddy K Koduri Sri Harsha I Sahasra | F18: Vignan Institute of Technology and Science | G18: CSE (DS) CSE CSE (DS) | H18: 3rd Year | I18: 7093677995 9652867531 9347883612 | J18: =COUNTA('Team Wise'!D39:D41) -> 3
A19: 14 | B19: HV2-2026-OCT-6520 | C19: Black Pearl | D19: Artificial Intelligence (AI) | E19: Danthenapally Srivarshitha Gollapalli Chakradhar Chary Kota Uday Reddy | F19: CVR College of Engineering Sri Venkateshwara College of Engineering CVR College of Engineering | G19: CSE (DS) CSE (AI&ML) CSE (DS) | H19: 2nd Year | I19: 6309934781 7013280417 9347004550 | J19: =COUNTA('Team Wise'!D42:D44) -> 3
A20: 15 | B20: HV2-2026-OCT-4594 | C20: BoldCoders | D20: Artificial Intelligence (AI) | E20: Kasoju SpuranChandra Maddineni Yashashwini Pothuganti Sonalika | F20: Vignan Institute of Technology and Science | G20: CSE | H20: 2nd Year | I20: 9515067709 7793963851 8332044969 | J20: =COUNTA('Team Wise'!D45:D47) -> 3
A21: 16 | B21: HV2-2026-OCT-3585 | C21: BrainRot Brats | D21: Artificial Intelligence (AI) | E21: Aasheerwad Sandhyapogu Vishal reddy Syed Omer | F21: Vignan Institute of Technology and Science | G21: CSE (AI&ML) | H21: 3rd Year | I21: 7702363562 9849019832 7981537348 | J21: =COUNTA('Team Wise'!D48:D50) -> 3
A22: 17 | B22: HV2-2026-OCT-3629 | C22: BroCode | D22: Artificial Intelligence (AI) | E22: Varshini Bodige Harika Gummalla Kancharla Manish Kumar | F22: Vignan Institute of Technology and Science | G22: CSE | H22: 2nd Year | I22: 9182392386 9121555751 9948437820 | J22: =COUNTA('Team Wise'!D51:D53) -> 3
A23: 18 | B23: HV2-2026-OCT-4616 | C23: Bug Slayers | D23: Artificial Intelligence (AI) | E23: Padarthi Divya Sri Chirra Hasini Chamakura Yamini | F23: ACE Engineering College | G23: CSE (DS) CSE (AI&ML) CSE (DS) | H23: 2nd Year | I23: 9618719572 8341223438 7989609328 | J23: =COUNTA('Team Wise'!D54:D56) -> 3
A24: 19 | B24: HV2-2026-OCT-9242 | C24: Clause's Plan | D24: Artificial Intelligence (AI) | E24: Sashreek Reddy Kanaparthy Aryan Sai Chandrakanth | F24: Vignan Institute of Technology and Science | G24: CSE | H24: 2nd Year | I24: 9059949889 7416481279 6281696284 | J24: =COUNTA('Team Wise'!D57:D59) -> 3
A25: 20 | B25: HV2-2026-OCT-9150 | C25: Code & Slay | D25: Artificial Intelligence (AI) | E25: Anthati Ruthika Ithagoni Jyothsnasri Kusuru Divya | F25: Vignan Institute of Technology and Science | G25: CSE | H25: 3rd Year | I25: 9705884131 9121954394 9391433725 | J25: =COUNTA('Team Wise'!D60:D62) -> 3
A26: 21 | B26: HV2-2026-OCT-5745 | C26: Code Blooded | D26: Artificial Intelligence (AI) | E26: Yamini Thirumani Puvvadi Sakhitha Harshitha Puliroju | F26: G Narayanamma Institute of Technology and Science (GNITS) | G26: CSE (DS) CSE (AI&ML) CSE (DS) | H26: 4th Year | I26: 7995693895 9398899334 6305406660 | J26: =COUNTA('Team Wise'!D63:D65) -> 3
A27: 22 | B27: HV2-2026-OCT-6128 | C27: Code cube | D27: Artificial Intelligence (AI) | E27: Padakanti varsha Ubbu Rohini Palsam Maneesha | F27: Vignan Institute of Technology and Science | G27: CSE | H27: 3rd Year | I27: 6304218536 9603272908 9014710274 | J27: =COUNTA('Team Wise'!D66:D68) -> 3
A28: 23 | B28: HV2-2026-OCT-4305 | C28: Code rush | D28: Artificial Intelligence (AI) | E28: chegurisahasra21 chegurisamaghna21 shivaniappala | F28: Vignan Institute of Technology and Science | G28: CSE | H28: 3rd Year | I28: 9573609225 9849747585 6304128615 | J28: =COUNTA('Team Wise'!D69:D71) -> 3
A29: 24 | B29: HV2-2026-OCT-5660 | C29: Code titans | D29: Artificial Intelligence (AI) | E29: Chada Vaishnavi Akshitha Deshagoni Srividya Alubilli | F29: Marri Laxman Reddy Institute of Technology and Management (MLRITM) | G29: CSE (AI&ML) | H29: 2nd Year | I29: 7702498268 9030380871 6281084832 | J29: =COUNTA('Team Wise'!D72:D74) -> 3
A30: 25 | B30: HV2-2026-OCT-9845 | C30: Code titans | D30: Artificial Intelligence (AI) | E30: Chindam Keerthana janipella sindhu tadaka akhila | F30: Vignan Institute of Technology and Science | G30: CSE (AI&ML) | H30: 2nd Year | I30: 8179992289 9573376307 8688196471 | J30: =COUNTA('Team Wise'!D75:D77) -> 3
A31: 26 | B31: HV2-2026-OCT-8620 | C31: Code × Crash | D31: Artificial Intelligence (AI) | E31: Daroori Abhignya S.Ruchitha Tejaswi Pendyala | F31: Vignan's Institute of Management and Technology for Women (VMTW) | G31: CSE (DS) | H31: 3rd Year | I31: 8247203142 9866193388 9391281815 | J31: =COUNTA('Team Wise'!D78:D80) -> 3
A32: 27 | B32: HV2-2026-OCT-6582 | C32: CodeAlpha | D32: Artificial Intelligence (AI) | E32: Golconda Yeshwanth Kumar Polepaka Mahesh Velpula Vyshali | F32: Anurag Engineering College (Kodad) | G32: CSE | H32: 3rd Year | I32: 7075320652 7013197272 9542224334 | J32: =COUNTA('Team Wise'!D81:D83) -> 3
A33: 28 | B33: HV2-2026-OCT-5487 | C33: CodeHelix | D33: Artificial Intelligence (AI) | E33: G.Rishitha K.shirisha Gondi Soumya reddy | F33: Vignan Institute of Technology and Science | G33: CSE | H33: 3rd Year | I33: 7997182157 9652166330 9848546409 | J33: =COUNTA('Team Wise'!D84:D86) -> 3
A34: 29 | B34: HV2-2026-OCT-3917 | C34: CodeMatriX | D34: Artificial Intelligence (AI) | E34: Krishna Chaitanya Anugu Nandini Yarramada Ashna Reddy Gangapuram | F34: Vignan Institute of Technology and Science | G34: CSE | H34: 2nd Year | I34: 7780401460 9063401449 9393833639 | J34: =COUNTA('Team Wise'!D87:D89) -> 3
A35: 30 | B35: HV2-2026-OCT-1244 | C35: CodeMind | D35: Artificial Intelligence (AI) | E35: BHUDHALA MADHAVI KASULA AKSHAYA PREETHI BARADO | F35: Vignan Institute of Technology and Science | G35: CSE (DS) | H35: 2nd Year | I35: 8179752894 9032915256 9603554602 | J35: =COUNTA('Team Wise'!D90:D92) -> 3
A36: 31 | B36: HV2-2026-OCT-6039 | C36: Codefusion | D36: Artificial Intelligence (AI) | E36: SHIVANI KURMA Ch Karthik Shaik Momin | F36: Marri Laxman Reddy Institute of Technology and Management (MLRITM) | G36: CSE (AI&ML) | H36: 3rd Year | I36: 9398471837 9493317442 9133153170 | J36: =COUNTA('Team Wise'!D93:D95) -> 3
A37: 32 | B37: HV2-2026-OCT-5283 | C37: Coders | D37: Artificial Intelligence (AI) | E37: Neelam Anjali Nikhil Mudigonda Srujana Sadhu | F37: KL University (KLH) | G37: CSE | H37: 4th Year 3rd Year 3rd Year | I37: 9985859422 8341664756 9491516765 | J37: =COUNTA('Team Wise'!D96:D98) -> 3
A38: 33 | B38: HV2-2026-OCT-8480 | C38: Coderush | D38: Artificial Intelligence (AI) | E38: Erra Akshitha Varsha Mattaparthi Damaraju guru Lakshmi manasa | F38: Sphoorthy Engineering College Vignan Institute of Technology and Science Matrusri Engineering College | G38: AI&ML CSE IT | H38: 3rd Year | I38: 9441830190 7989068069 6309804359 | J38: =COUNTA('Team Wise'!D99:D101) -> 3
A39: 34 | B39: HV2-2026-OCT-2455 | C39: Codex | D39: Artificial Intelligence (AI) | E39: Lingamgunta Pranav Abhivarun Bashapaka Shivashritej | F39: Vignan Institute of Technology and Science | G39: CSE | H39: 2nd Year | I39: 8179146995 9515659290 8179222881 | J39: =COUNTA('Team Wise'!D102:D104) -> 3
A40: 35 | B40: HV2-2026-OCT-5681 | C40: Codex | D40: Artificial Intelligence (AI) | E40: KARIVEDA ABHINAV REDDY Kashamalla spandana Ulloju anitha | F40: Vignan Institute of Technology and Science | G40: CSE (AI&ML) | H40: 3rd Year | I40: 8985144115 9182364536 9014367708 | J40: =COUNTA('Team Wise'!D105:D107) -> 3
A41: 36 | B41: HV2-2026-OCT-5738 | C41: Codinjas | D41: Artificial Intelligence (AI) | E41: POLE RAVITEJA Varahala Vishal Yashraj Bhuvakar | F41: Vardhaman College of Engineering VMEG VMEG | G41: IT ECE ECE | H41: 3rd Year | I41: 7569057424 9701417442 7386614171 | J41: =COUNTA('Team Wise'!D108:D110) -> 3
A42: 37 | B42: HV2-2026-OCT-3076 | C42: Cognivyx | D42: Artificial Intelligence (AI) | E42: Katkuri Lohitha Sravani Nomula Sowmya Patnam | F42: Vignan Institute of Technology and Science | G42: CSE | H42: 2nd Year | I42: 7386202278 9505472736 8374564428 | J42: =COUNTA('Team Wise'!D111:D113) -> 3
A43: 38 | B43: HV2-2026-OCT-3475 | C43: Cold Start | D43: Artificial Intelligence (AI) | E43: Bidarani Swathika Kannareddy Sriharini Sathuri Kavya | F43: Vignan Institute of Technology and Science | G43: CSE (DS) | H43: 3rd Year | I43: 8985668619 8978132468 9441082597 | J43: =COUNTA('Team Wise'!D114:D116) -> 3
A44: 39 | B44: HV2-2026-OCT-9141 | C44: CoreX | D44: Artificial Intelligence (AI) | E44: Kavya deepika Hemasri Lakshmi prassana | F44: Vignan's Institute of Management and Technology for Women (VMTW) | G44: CSE CSE (DS) CSE (DS) | H44: 3rd Year | I44: 9494880185 8125617760 9490082345 | J44: =COUNTA('Team Wise'!D117:D119) -> 3
...

Sheet CS
A5: Team No. | B5: Registration ID | C5: Team Name | D5: Track | E5: Team Member Names | F5: College | G5: Branch | H5: Year | I5: Phone No. | J5: Members
A6: 1 | B6: HV2-2026-OCT-2624 | C6: Astra-gpt6 | D6: Cyber Security | E6: Haneef Mohammad Billapati Yashwanth Reddy Mothuku Keerthana | F6: Vignan Institute of Technology and Science | G6: CSE | H6: 3rd Year | I6: 9676208652 9441819445 9100524513 | J6: =COUNTA('Team Wise'!D354:D356) -> 3
A7: 2 | B7: HV2-2026-OCT-6875 | C7: Axiom Three | D7: Cyber Security | E7: maithrika banda Baigani Prabhu Teja Manga Vikram | F7: Vignan Institute of Technology and Science Vignan Institute of Technology and Science Matrusri Engineering College | G7: CSE (DS) EEE CSE (DS) | H7: 3rd Year | I7: 8008804364 9963973677 9848306153 | J7: =COUNTA('Team Wise'!D357:D359) -> 3
A8: 3 | B8: HV2-2026-OCT-8554 | C8: Catalyst | D8: Cyber Security | E8: Kambhalapalli srinadh Chinthala shiva rama krishna Bollam Ajay | F8: Pallavi Engineering College | G8: CSE | H8: 3rd Year 2nd Year 2nd Year | I8: 7032363755 7670986689 7396967187 | J8: =COUNTA('Team Wise'!D360:D362) -> 3
A9: 4 | B9: HV2-2026-OCT-1915 | C9: Code Crusaders | D9: Cyber Security | E9: Ghanta Kowshik Kumar Yandamuri Venkat Bommisetty Pranava Sree | F9: Vignan Institute of Technology and Science | G9: CSE | H9: 4th Year 2nd Year 2nd Year | I9: 9652491275 9492513338 8977527418 | J9: =COUNTA('Team Wise'!D363:D365) -> 3
A10: 5 | B10: HV2-2026-OCT-3310 | C10: CyberNova | D10: Cyber Security | E10: Cheguri Varshasree Bujagouni Sakshitha Ravula Ashvitha | F10: Marri Laxman Reddy Institute of Technology and Management (MLRITM) | G10: ECE | H10: 2nd Year | I10: 8125192448 9490509459 6305566155 | J10: =COUNTA('Team Wise'!D366:D368) -> 3
A11: 6 | B11: HV2-2026-OCT-5095 | C11: CyberVanguard | D11: Cyber Security | E11: VAMANABATLA SAMANVITHA SHARMA Alladi Anjana Sri Binnala Ritu | F11: Marri Laxman Reddy Institute of Technology and Management (MLRITM) | G11: ECE | H11: 2nd Year | I11: 9911998448 9248439709 6309845685 | J11: =COUNTA('Team Wise'!D369:D371) -> 3
A12: 7 | B12: HV2-2026-OCT-3193 | C12: Cyvanta | D12: Cyber Security | E12: Valaboju Hamsika S.Arthi Jahnavi | F12: Vignan Institute of Technology and Science | G12: AIDS AIDS CSE | H12: 3rd Year | I12: 9440801653 9666122276 8712197493 | J12: =COUNTA('Team Wise'!D372:D374) -> 3
A13: 8 | B13: HV2-2026-OCT-1648 | C13: DRISTI | D13: Cyber Security | E13: VISHNU VARDHAN CHIRRAPU Nimmala Indu Bhukya Monali | F13: ACE Engineering College | G13: IT AIDS CSE (DS) | H13: 3rd Year 4th Year 2nd Year | I13: 9392980085 6304336527 9392458375 | J13: =COUNTA('Team Wise'!D375:D377) -> 3
A14: 9 | B14: HV2-2026-OCT-8167 | C14: Grand vice | D14: Cyber Security | E14: Talasani Mithul Reddy C Harshit J Sai Jashwanth | F14: Vignan Institute of Technology and Science | G14: IT | H14: 3rd Year | I14: 9948743042 9381258576 9494329249 | J14: =COUNTA('Team Wise'!D378:D380) -> 3
A15: 10 | B15: HV2-2026-OCT-4328 | C15: HackZen | D15: Cyber Security | E15: Afsha Mehreen Tarini Yamini | F15: ACE Engineering College | G15: CSE (DS) | H15: 2nd Year | I15: 7702952655 8019029777 8125664708 | J15: =COUNTA('Team Wise'!D381:D383) -> 3
A16: 11 | B16: HV2-2026-OCT-5039 | C16: Infinity coders | D16: Cyber Security | E16: Akhil Jammula Aerasani Pradeepthi Sai samhitha | F16: Vignan Institute of Technology and Science Anurag University Matrusri Engineering College | G16: CSE (DS) CSE CSE | H16: 3rd Year | I16: 9494297547 8019196392 7396291925 | J16: =COUNTA('Team Wise'!D384:D386) -> 3
A17: 12 | B17: HV2-2026-OCT-6290 | C17: LUFFY | D17: Cyber Security | E17: M.Sajay S.sri Manikandan Kanhaiya lal dindor | F17: AVCE, Pottalkulam | G17: CSE | H17: 3rd Year | I17: 7871090927 8428401607 9509374598 | J17: =COUNTA('Team Wise'!D387:D389) -> 3
A18: 13 | B18: HV2-2026-OCT-1291 | C18: LockIn | D18: Cyber Security | E18: Bhanu Teja Gupta Vuppu Md Muzaffar B Saharsha | F18: CVR College of Engineering | G18: CSE | H18: 3rd Year | I18: 9440394651 6300045034 9063123199 | J18: =COUNTA('Team Wise'!D390:D392) -> 3
A19: 14 | B19: HV2-2026-OCT-8109 | C19: Phantomx | D19: Cyber Security | E19: Shaik Shaher Bano Noorjahan Vedere Siri Chandana Reddy B.Divya | F19: Vignan Institute of Technology and Science | G19: CSE | H19: 3rd Year | I19: 9963004559 9182614305 9390598541 | J19: =COUNTA('Team Wise'!D393:D395) -> 3
A20: 15 | B20: HV2-2026-OCT-9688 | C20: Sathwika | D20: Cyber Security | E20: Srinidhi Narani Sathwika Reddy Gade Ristesh kota | F20: Vignan Institute of Technology and Science Vignan Institute of Technology and Science Mahindra University | G20: CSE (DS) AIDS CSE (DS) | H20: 3rd Year 3rd Year 2nd Year | I20: 6309637995 9676834000 8332907441 | J20: =COUNTA('Team Wise'!D396:D398) -> 3
A21: 16 | B21: HV2-2026-OCT-2367 | C21: Scout Regiment | D21: Cyber Security | E21: D.Bharanish K.Tejaswini N.Koushal | F21: Vignan's Foundation for Science, Technology & Research (Vignan University) | G21: CSE (DS) CSE CSE (DS) | H21: 1st Year | I21: 7396337438 95737361258 9014001844 | J21: =COUNTA('Team Wise'!D399:D401) -> 3
A22: 17 | B22: HV2-2026-OCT-3987 | C22: Syntax error | D22: Cyber Security | E22: T vikram M Vishal P harshith | F22: Vignan Institute of Technology and Science | G22: IT | H22: 3rd Year | I22: 9705048160 7330869671 8121732531 | J22: =COUNTA('Team Wise'!D402:D404) -> 3
A23: 18 | B23: HV2-2026-OCT-5055 | C23: Team Rolex | D23: Cyber Security | E23: Tanneru Naga Charan Tej Anampally Sai Rakshith Oruganti Pranav Sri Datta | F23: Vignan Institute of Technology and Science | G23: CSE | H23: 3rd Year | I23: 6304510542 8187059394 9490262822 | J23: =COUNTA('Team Wise'!D405:D407) -> 3
A24: 19 | B24: HV2-2026-OCT-8785 | C24: Team Void | D24: Cyber Security | E24: Nikhil Reddy P Sathwika M Sanjay | F24: Vignan Institute of Technology and Science | G24: CSE (DS) | H24: 3rd Year | I24: 9491659096 9392627325 9849655411 | J24: =COUNTA('Team Wise'!D408:D410) -> 3
A25: 20 | B25: HV2-2026-OCT-6282 | C25: Team Vulcan | D25: Cyber Security | E25: G.Sai Srihas K.Swapnil B.Bharadwaj | F25: Vignan Institute of Technology and Science Keshav Memorial Institute of Technology (KMIT) Neil Gogte Institute of Technology | G25: CSE CSE (AI&ML) CSE (AI&ML) | H25: 3rd Year | I25: 9652692268 7207800660 9391237318 | J25: =COUNTA('Team Wise'!D411:D413) -> 3
A26: 21 | B26: HV2-2026-OCT-3686 | C26: Trinetra | D26: Cyber Security | E26: Ramya Mandava S.pranathi P.Bhavya | F26: Vignan Institute of Technology and Science | G26: CSE | H26: 3rd Year | I26: 6303283079 8008606832 9494508239 | J26: =COUNTA('Team Wise'!D414:D416) -> 3
A27: 22 | B27: HV2-2026-OCT-3333 | C27: Trojan Horses | D27: Cyber Security | E27: S SAJID BASHA B ABHINAV ESHWAR REDDY | F27: Vignan Institute of Technology and Science | G27: CSE (DS) | H27: 3rd Year | I27: 7075107431 7416009806 6281519839 | J27: =COUNTA('Team Wise'!D417:D419) -> 3
A28: 23 | B28: HV2-2026-OCT-7164 | C28: VignanTree | D28: Cyber Security | E28: Alakuchi Anirudh Syed Ghayas Ur Rehman J Venkata Sai Ravi Raj | F28: Vignan Institute of Technology and Science | G28: CSE | H28: 3rd Year | I28: 9121094699 9666164416 8008845058 | J28: =COUNTA('Team Wise'!D420:D422) -> 3
A29: 24 | B29: HV2-2026-OCT-2114 | C29: cybershield 2.0 | D29: Cyber Security | E29: Pasula Reshma Gandeti Goutham R.Sathwika | F29: AVN Institute of Engineering and Technology Vignan Institute of Technology and Science Vignan Institute of Technology and Science | G29: CSE CSE (AI&ML) CSE (AI&ML) | H29: 3rd Year | I29: 9652982759 6309123856 9032352474 | J29: =COUNTA('Team Wise'!D423:D425) -> 3
A30: 25 | B30: HV2-2026-OCT-4496 | C30: espresso | D30: Cyber Security | E30: T Hemanth K Spoorthi Reddy R pranay Kumar | F30: Vignan's Foundation for Science, Technology & Research (Vignan University) | G30: CSE (DS) | H30: 1st Year | I30: 9014106846 9030350730 7989235132 | J30: =COUNTA('Team Wise'!D426:D428) -> 3
A31: 26 | B31: HV2-2026-OCT-6975 | C31: prisha | D31: Cyber Security | E31: Prisha Priyanjal milika reddy Akshitha Reddy | F31: Vignan Institute of Technology and Science | G31: AIDS | H31: 3rd Year | I31: 9493903251 9573604089 9989392885 | J31: =COUNTA('Team Wise'!D429:D431) -> 3

Sheet IOT
A5: Team No. | B5: Registration ID | C5: Team Name | D5: Track | E5: Team Member Names | F5: College | G5: Branch | H5: Year | I5: Phone No. | J5: Members
A6: 1 | B6: HV2-2026-OCT-6458 | C6: 3gger pulse | D6: Internet of Things (IOT) | E6: Likhitha Vinnakota Molankar Tejeshwini Yanagandala Tejesh | F6: Vignan Institute of Technology and Science | G6: ECE CSE (DS) CSE (DS) | H6: 3rd Year | I6: 7893770062 9390792019 7893818817 | J6: =COUNTA('Team Wise'!D406:D408) -> 3 | K6: =COUNTIF('Team Wise'!K406:K408,"Present") -> 0
A7: 2 | B7: HV2-2026-OCT-9520 | C7: ERROR-404 | D7: Internet of Things (IOT) | E7: R.Vidya Shankar vemuri vijayeswarara rao N. Meenakshi Srinidhi | F7: Vignan Institute of Technology and Science | G7: CSE (AI&ML) CSE (AI&ML) EIE | H7: 3rd Year | I7: 9360921529 8332932136 7207403604 | J7: =COUNTA('Team Wise'!D409:D411) -> 3 | K7: =COUNTIF('Team Wise'!K409:K411,"Present") -> 0
A8: 3 | B8: HV2-2026-OCT-6161 | C8: Mechanical Mavericks | D8: Internet of Things (IOT) | E8: Pravinya Valluri Bandaru Bhuvaneshwari Gopagani Sanjay | F8: Vignan Institute of Technology and Science | G8: MECH | H8: 3rd Year | I8: 9110329739 9849660756 9063431086 | J8: =COUNTA('Team Wise'!D412:D414) -> 3 | K8: =COUNTIF('Team Wise'!K412:K414,"Present") -> 0
A9: 4 | B9: HV2-2026-OCT-6112 | C9: Nullvector | D9: Internet of Things (IOT) | E9: Pothuganti Ganateju Avvaru sriya PANGULURI VYSHNAVI | F9: Vignan's Foundation for Science, Technology & Research (Vignan University) | G9: ECE | H9: 3rd Year | I9: 9502479610 7075229139 8919416257 | J9: =COUNTA('Team Wise'!D415:D417) -> 3 | K9: =COUNTIF('Team Wise'!K415:K417,"Present") -> 0
A10: 5 | B10: HV2-2026-OCT-5380 | C10: Ravens | D10: Internet of Things (IOT) | E10: Vanavoju Varshitha Vadakattu Bharath B.Ashwith | F10: Vignan Institute of Technology and Science | G10: CSE (DS) | H10: 3rd Year | I10: 9390442352 9063639625 7386770214 | J10: =COUNTA('Team Wise'!D418:D420) -> 3 | K10: =COUNTIF('Team Wise'!K418:K420,"Present") -> 0
A11: 6 | B11: HV2-2026-OCT-4925 | C11: Shouryanga | D11: Internet of Things (IOT) | E11: E Rithvk Nag Karunya Rajasekhar Kothapalli CH Harshit | F11: Vignan Institute of Technology and Science | G11: ECE CSE IT | H11: 2nd Year | I11: 7995712308 9398191633 9014516625 | J11: =COUNTA('Team Wise'!D421:D423) -> 3 | K11: =COUNTIF('Team Wise'!K421:K423,"Present") -> 0
A12: 7 | B12: HV2-2026-OCT-3998 | C12: TEAM FALCONS | D12: Internet of Things (IOT) | E12: PENTA RISHI VASTHAL CHAKRAHARI HARSHITH RAJU MADHAVARAM JASWANTH | F12: Vignan Institute of Technology and Science | G12: CSE | H12: 2nd Year | I12: 9110764728 6303326553 7893784959 | J12: =COUNTA('Team Wise'!D424:D426) -> 3 | K12: =COUNTIF('Team Wise'!K424:K426,"Present") -> 0
A13: 8 | B13: HV2-2026-OCT-8439 | C13: Titans | D13: Internet of Things (IOT) | E13: Siddartha Samala Y Harsha krishna Burri Ruthwik | F13: Vignan Institute of Technology and Science | G13: CSE (DS) | H13: 3rd Year | I13: 9030520458 8125418662 9515276423 | J13: =COUNTA('Team Wise'!D427:D429) -> 3 | K13: =COUNTIF('Team Wise'!K427:K429,"Present") -> 0

Sheet NA
A5: Team No. | B5: Registration ID | C5: Team Name | D5: Track | E5: Team Member Names | F5: College | G5: Branch | H5: Year | I5: Phone No. | J5: Members
A6: 1 | B6: UCQP3790 | C6: EVA-01 | D6: Not specified | E6: Taufiq Mohammad Sai Ashika Katragadda Ashwaq Mohammad | F6: Institute of Aeronautical Engineering (IARE) Nalla Narasimha Reddy Group of Institutions (NNRG) | G6: ECE Other ECE | H6: 3rd Year 3rd Year 2nd Year | I6: Not provided Not provided Not provided | J6: =COUNTA('Team Wise'!D422:D424) -> 3
A7: 2 | B7: UN79QH19 | C7: Forward Minds | D7: Not specified | E7: RAVITEJA Dadi Prasastha D Satya Lokesh Dharamavarapu | F7: V.S.M College of Engineering | G7: CSE | H7: 3rd Year | I7: Not provided Not provided Not provided | J7: =COUNTA('Team Wise'!D425:D427) -> 3
A8: 3 | B8: U71HW20J | C8: Impact hackers | D8: Not specified | E8: Sriphani Dhanwanth Tharun Abhinay Sitaram | F8: Anurag Engineering College (Kodad) | G8: CSE | H8: 3rd Year | I8: Not provided Not provided Not provided | J8: =COUNTA('Team Wise'!D428:D430) -> 3
A9: 4 | B9: UZ2O2K21 | C9: Smart tech | D9: Not specified | E9: Hari Bilapudi Lavanya Chelle Anusha Dwarampudi | F9: V.S.M College of Engineering | G9: CSE | H9: 3rd Year | I9: Not provided Not provided Not provided | J9: =COUNTA('Team Wise'!D431:D433) -> 3

Sheet 1ST
A5: Team No. | B5: Registration ID | C5: Team Name | D5: Track | E5: Team Member Names | F5: College | G5: Branch | H5: Year | I5: Phone No. | J5: Members
A6: 1 | B6: HV2-2026-OCT-4698 | C6: #HackNova | D6: Artificial Intelligence (AI) | E6: Pasham Akanksha Reddy Srinivas Nayak Ramavath Pasham Hrithik Reddy | F6: Vignan Institute of Technology and Science | G6: AIDS | H6: 1st Year | I6: 9652601387 7680028395 8985540655 | J6: 3
A7: 2 | B7: HV2-2026-OCT-7433 | C7: HACK HUSTLERS | D7: Artificial Intelligence (AI) | E7: MD ISMAIL ANSARI A Lucky K.Chethan | F7: Vignan's Foundation for Science, Technology & Research (Vignan University) | G7: CSE | H7: 1st Year | I7: 8235520824 8309838926 7601006224 | J7: 3
A8: 3 | B8: HV2-2026-OCT-3356 | C8: Hack Terminators | D8: Artificial Intelligence (AI) | E8: Patil.RamyaSri Singireddy.Siri Yellanki.Sirivennela | F8: Vignan Institute of Technology and Science | G8: AIDS | H8: 1st Year | I8: 8341507702 7386864751 7095891137 | J8: 3
A9: 4 | B9: HV2-2026-OCT-6702 | C9: Ragnar | D9: Artificial Intelligence (AI) | E9: Sreeraj Thalappalli Atharva Malgatti Naqhi Niazi | F9: Golden Gate University | G9: AI&ML AI&ML IT | H9: 1st Year | I9: 7306221632 9322380971 7021677094 | J9: 3
A10: 5 | B10: HV2-2026-OCT-3677 | C10: Syntax.Error | D10: Artificial Intelligence (AI) | E10: Aashrith Gupta Nitika krishna.K Khushi Thalla | F10: Vignan Institute of Technology and Science | G10: IT | H10: 1st Year | I10: 8248049855 9030828356 8897483147 | J10: 3
A11: 6 | B11: HV2-2026-OCT-9957 | C11: TUMORTRACKERS | D11: Artificial Intelligence (AI) | E11: A.LaxmiKishore B.ShubanSai S.JayaPrakash | F11: Vignan Institute of Technology and Science | G11: AIDS | H11: 1st Year | I11: 9063455200 8978698459 9505199866 | J11: 3
A12: 7 | B12: HV2-2026-OCT-3140 | C12: Tech Buddies | D12: Artificial Intelligence (AI) | E12: LAKSHMI NARASIMHA REDDY MARAM RISHI RAJ Ravi Shankar | F12: Keshav Memorial Institute of Technology (KMIT) | G12: CSE | H12: 1st Year | I12: 8019015526 7396956081 8125947299 | J12: 3
A13: 8 | B13: HV2-2026-OCT-4175 | C13: VisionX | D13: Artificial Intelligence (AI) | E13: G venkata satvik Pola Sadhika Eslavath varun | F13: Vignan Institute of Technology and Science Vignan Institute of Technology and Science CVR College of Engineering | G13: CSE (AI&ML) | H13: 1st Year | I13: 9347894341 7842514989 8187099935 | J13: 3
A14: 9 | B14: HV2-2026-OCT-6517 | C14: WeGotLatent | D14: Artificial Intelligence (AI) | E14: Sri Charan Varma P Shivadeekshith Reddy S R Sree Sai Lochan | F14: Vignan Institute of Technology and Science | G14: CSE | H14: 1st Year | I14: 7013787104 9640861234 9966009403 | J14: 3
A15: 10 | B15: HV2-2026-OCT-2639 | C15: open bot swarms | D15: Artificial Intelligence (AI) | E15: VENEPALLI AJAY KRUTHIK SAI VANAPALLY PRANEETH REDDY Srinidhimaringnati | F15: Vignan's Foundation for Science, Technology & Research (Vignan University) | G15: ECE CSE CSE (AI&ML) | H15: 1st Year | I15: 6281035202 8978881882 9398501119 | J15: 3
A16: 11 | B16: HV2-2026-OCT-2367 | C16: Scout Regiment | D16: Cyber Security | E16: D.Bharanish K.Tejaswini N.Koushal | F16: Vignan's Foundation for Science, Technology & Research (Vignan University) | G16: CSE (DS) CSE CSE (DS) | H16: 1st Year | I16: 7396337438 95737361258 9014001844 | J16: 3
A17: 12 | B17: HV2-2026-OCT-4496 | C17: espresso | D17: Cyber Security | E17: T Hemanth K Spoorthi Reddy R pranay Kumar | F17: Vignan's Foundation for Science, Technology & Research (Vignan University) | G17: CSE (DS) | H17: 1st Year | I17: 9014106846 9030350730 7989235132 | J17: 3

Sheet 2ND
A5: Team No. | B5: Registration ID | C5: Team Name | D5: Track | E5: Team Member Names | F5: College | G5: Branch | H5: Year | I5: Phone No. | J5: Members
A6: 1 | B6: HV2-2026-OCT-1818 | C6: AI mavericks | D6: Artificial Intelligence (AI) | E6: Vaggu Sahasra krupalini kasoju Gangapuram Sai Charan | F6: Vignan Institute of Technology and Science | G6: CSE (DS) CIVIL MECH | H6: 2nd Year | I6: 9908982106 9100326179 9666895769 | J6: 3 | K6: 0
A7: 2 | B7: HV2-2026-OCT-1348 | C7: AI-tians | D7: Artificial Intelligence (AI) | E7: Mikkilineni Pravarshitha P Pranathi SINGAM SAI HARSHITH | F7: Vignan Institute of Technology and Science | G7: CSE (AI&ML) | H7: 2nd Year | I7: 8985359921 9381261938 7660042977 | J7: 3 | K7: 0
A8: 3 | B8: HV2-2026-OCT-4878 | C8: Advitheeya | D8: Artificial Intelligence (AI) | E8: Badugu Nigama Nakarakanti Yuva Keerthi Kan Kushi Kumari | F8: Vignan Institute of Technology and Science | G8: AIDS | H8: 2nd Year | I8: 7032177918 8074382611 9490706546 | J8: 3 | K8: 0
A9: 4 | B9: HV2-2026-OCT-4906 | C9: AiFinishers | D9: Artificial Intelligence (AI) | E9: Badavath vishnu Boya mukesh Janga chandan | F9: Vignan Institute of Technology and Science | G9: CSE (DS) | H9: 2nd Year | I9: 7396616379 7815858411 8247030165 | J9: 3 | K9: 0
A10: 5 | B10: HV2-2026-OCT-2695 | C10: Alide | D10: Artificial Intelligence (AI) | E10: Abhiram Mohammad Arif Sathish | F10: Vignan Institute of Technology and Science | G10: CSE (AI&ML) | H10: 2nd Year | I10: 8008189293 8074047607 8712214574 | J10: 3 | K10: 0
A11: 6 | B11: HV2-2026-OCT-7565 | C11: All stars | D11: Artificial Intelligence (AI) | E11: katakam supraja N.arun M ARAVIND | F11: Vignan Institute of Technology and Science | G11: CSE | H11: 2nd Year | I11: 9490948538 8639459203 6281094261 | J11: 3 | K11: 0
A12: 7 | B12: HV2-2026-OCT-4338 | C12: BLITZ | D12: Artificial Intelligence (AI) | E12: Tejeshwar Reddy Addula Byreddy Sushank Reddy Chandaluri Sri Harsha | F12: Vignan Institute of Technology and Science | G12: CSE (AI&ML) | H12: 2nd Year | I12: 7382838743 8332051480 9100865190 | J12: 3 | K12: 0
A13: 8 | B13: HV2-2026-OCT-6520 | C13: Black Pearl | D13: Artificial Intelligence (AI) | E13: Danthenapally Srivarshitha Gollapalli Chakradhar Chary Kota Uday Reddy | F13: CVR College of Engineering Sri Venkateshwara College of Engineering CVR College of Engineering | G13: CSE (DS) CSE (AI&ML) CSE (DS) | H13: 2nd Year | I13: 6309934781 7013280417 9347004550 | J13: 3 | K13: 0
A14: 9 | B14: HV2-2026-OCT-4594 | C14: BoldCoders | D14: Artificial Intelligence (AI) | E14: Kasoju SpuranChandra Maddineni Yashashwini Pothuganti Sonalika | F14: Vignan Institute of Technology and Science | G14: CSE | H14: 2nd Year | I14: 9515067709 7793963851 8332044969 | J14: 3 | K14: 0
A15: 10 | B15: HV2-2026-OCT-3629 | C15: BroCode | D15: Artificial Intelligence (AI) | E15: Varshini Bodige Harika Gummalla Kancharla Manish Kumar | F15: Vignan Institute of Technology and Science | G15: CSE | H15: 2nd Year | I15: 9182392386 9121555751 9948437820 | J15: 3 | K15: 0
A16: 11 | B16: HV2-2026-OCT-4616 | C16: Bug Slayers | D16: Artificial Intelligence (AI) | E16: Padarthi Divya Sri Chirra Hasini Chamakura Yamini | F16: ACE Engineering College | G16: CSE (DS) CSE (AI&ML) CSE (DS) | H16: 2nd Year | I16: 9618719572 8341223438 7989609328 | J16: 3 | K16: 0
A17: 12 | B17: HV2-2026-OCT-9242 | C17: Clause's Plan | D17: Artificial Intelligence (AI) | E17: Sashreek Reddy Kanaparthy Aryan Sai Chandrakanth | F17: Vignan Institute of Technology and Science | G17: CSE | H17: 2nd Year | I17: 9059949889 7416481279 6281696284 | J17: 3 | K17: 0
... A88: 83 | B88: HV2-2026-OCT-3998 | C88: TEAM FALCONS | D88: Internet of Things (IOT) | E88: PENTA RISHI VASTHAL CHAKRAHARI HARSHITH RAJU MADHAVARAM JASWANTH | F88: Vignan Institute of Technology and Science | G88: CSE | H88: 2nd Year | I88: 9110764728 6303326553 7893784959 | J88: 3 | K88: 0

Sheet 3RD
A5: Team No. | B5: Registration ID | C5: Team Name | D5: Track | E5: Team Member Names | F5: College | G5: Branch | H5: Year | I5: Phone No. | J5: Members
A6: 1 | B6: HV2-2026-OCT-4899 | C6: ARITRA | D6: Artificial Intelligence (AI) | E6: Chathur M Vaahini G p sandeep | F6: Vignan Institute of Technology and Science | G6: AIDS AIDS CSE (DS) | H6: 2nd Year 2nd Year 3rd Year | I6: 9291619080 9391286222 7093447407 | J6: 3 | K6: 0
A7: 2 | B7: HV2-2026-OCT-4104 | C7: Aevora | D7: Artificial Intelligence (AI) | E7: Praseeja Sunkari Vanja Akshitha B.Vaishnavi | F7: Vignan Institute of Technology and Science | G7: CSE (AI&ML) CSE (DS) CSE (DS) | H7: 3rd Year | I7: 7842731141 7569220914 7416127993 | J7: 3 | K7: 0
A8: 3 | B8: HV2-2026-OCT-5358 | C8: Al Avengers | D8: Artificial Intelligence (AI) | E8: Sathu. Goutham Reddy Gudipelli. Manoj Kongari. Udayasree | F8: Vignan Institute of Technology and Science | G8: CSE (DS) CSE (AI&ML) CSE (DS) | H8: 3rd Year | I8: 9154184676 8179544286 6303036707 | J8: 3 | K8: 0
A9: 4 | B9: HV2-2026-OCT-4614 | C9: Algo squad | D9: Artificial Intelligence (AI) | E9: Poloju vasavi Mohammad saniya Pittala harika | F9: Vignan Institute of Technology and Science | G9: CSE | H9: 3rd Year | I9: 9392793987 9848364850 6309460308 | J9: 3 | K9: 0
A10: 5 | B10: HV2-2026-OCT-5946 | C10: Bits x Bytes | D10: Artificial Intelligence (AI) | E10: Neha Reddy K Koduri Sri Harsha I Sahasra | F10: Vignan Institute of Technology and Science | G10: CSE (DS) CSE CSE (DS) | H10: 3rd Year | I10: 7093677995 9652867531 9347883612 | J10: 3 | K10: 0
A11: 6 | B11: HV2-2026-OCT-3585 | C11: BrainRot Brats | D11: Artificial Intelligence (AI) | E11: Aasheerwad Sandhyapogu Vishal reddy Syed Omer | F11: Vignan Institute of Technology and Science | G11: CSE (AI&ML) | H11: 3rd Year | I11: 7702363562 9849019832 7981537348 | J11: 3 | K11: 0
A12: 7 | B12: HV2-2026-OCT-9150 | C12: Code & Slay | D12: Artificial Intelligence (AI) | E12: Anthati Ruthika Ithagoni Jyothsnasri Kusuru Divya | F12: Vignan Institute of Technology and Science | G12: CSE | H12: 3rd Year | I12: 9705884131 9121954394 9391433725 | J12: 3 | K12: 0
A13: 8 | B13: HV2-2026-OCT-6128 | C13: Code cube | D13: Artificial Intelligence (AI) | E13: Padakanti varsha Ubbu Rohini Palsam Maneesha | F13: Vignan Institute of Technology and Science | G13: CSE | H13: 3rd Year | I13: 6304218536 9603272908 9014710274 | J13: 3 | K13: 0
A14: 9 | B14: HV2-2026-OCT-4305 | C14: Code rush | D14: Artificial Intelligence (AI) | E14: chegurisahasra21 chegurisamaghna21 shivaniappala | F14: Vignan Institute of Technology and Science | G14: CSE | H14: 3rd Year | I14: 9573609225 9849747585 6304128615 | J14: 3 | K14: 0
A15: 10 | B15: HV2-2026-OCT-8620 | C15: Code × Crash | D15: Artificial Intelligence (AI) | E15: Daroori Abhignya S.Ruchitha Tejaswi Pendyala | F15: Vignan's Institute of Management and Technology for Women (VMTW) | G15: CSE (DS) | H15: 3rd Year | I15: 8247203142 9866193388 9391281815 | J15: 3 | K15: 0
A16: 11 | B16: HV2-2026-OCT-6582 | C16: CodeAlpha | D16: Artificial Intelligence (AI) | E16: Golconda Yeshwanth Kumar Polepaka Mahesh Velpula Vyshali | F16: Anurag Engineering College (Kodad) | G16: CSE | H16: 3rd Year | I16: 7075320652 7013197272 9542224334 | J16: 3 | K16: 0
A17: 12 | B17: HV2-2026-OCT-5487 | C17: CodeHelix | D17: Artificial Intelligence (AI) | E17: G.Rishitha K.shirisha Gondi Soumya reddy | F17: Vignan Institute of Technology and Science | G17: CSE | H17: 3rd Year | I17: 7997182157 9652166330 9848546409 | J17: 3 | K17: 0
